|Scenario|Result|ErrorMessage|ErrorStack|ErrorNormalized|StartDt|EndDt|
|step__alertrules_put|failed|(ResourceNotFound) The Resource 'Microsoft.OperationalInsights/workspaces/myWorkspace' under resource group 'clitestzeyavoifb7iy74smt2roepqce7sqojmb2rczyovhs6jjetiupnbujw4jiest7yumuipy' was not found. For more details please go to https://aka.ms/ARMResourceNotFoundFix|Traceback (most recent call last):   File "D:\repos\azure-cli\src\azure-cli-testsdk\azure\cli\testsdk\base.py", line 289, in _in_process_execute     self.exit_code = cli_ctx.invoke(shlex.split(command), out_file=stdout_buf) or 0   File "D:\repos\env3\lib\site-packages\knack\cli.py", line 226, in invoke     exit_code = self.exception_handler(ex)   File "D:\repos\azure-cli\src\azure-cli-core\azure\cli\core\__init__.py", line 119, in exception_handler     return handle_exception(ex)   File "D:\repo||2020-10-23 08:03:47.127155|2020-10-23 08:03:48.244756|
|step__alertrules_put2|failed|(ResourceNotFound) The Resource 'Microsoft.OperationalInsights/workspaces/myWorkspace' under resource group 'clitestzeyavoifb7iy74smt2roepqce7sqojmb2rczyovhs6jjetiupnbujw4jiest7yumuipy' was not found. For more details please go to https://aka.ms/ARMResourceNotFoundFix|Traceback (most recent call last):   File "D:\repos\azure-cli\src\azure-cli-testsdk\azure\cli\testsdk\base.py", line 289, in _in_process_execute     self.exit_code = cli_ctx.invoke(shlex.split(command), out_file=stdout_buf) or 0   File "D:\repos\env3\lib\site-packages\knack\cli.py", line 226, in invoke     exit_code = self.exception_handler(ex)   File "D:\repos\azure-cli\src\azure-cli-core\azure\cli\core\__init__.py", line 119, in exception_handler     return handle_exception(ex)   File "D:\repo||2020-10-23 08:03:48.259756|2020-10-23 08:03:48.923276|
|step__alertrules_put3|failed|The command failed. Exit code: 1|Traceback (most recent call last):   File "D:\repos\azure-cli-extensions\src\securityinsight\azext_sentinel\tests\__init__.py", line 66, in wrapper     ret = func_to_call(*args, **kwargs)   File "D:\repos\azure-cli-extensions\src\securityinsight\azext_sentinel\tests\latest\test_sentinel_scenario.py", line 63, in step__alertrules_put3     test.cmd('az sentinel alert-rule create '   File "D:\repos\azure-cli\src\azure-cli-testsdk\azure\cli\testsdk\base.py", line 167, in cmd     return execute(self.||2020-10-23 08:03:48.926274|2020-10-23 08:03:48.928275|
|step__alertrules_put4|failed|(ResourceNotFound) The Resource 'Microsoft.OperationalInsights/workspaces/myWorkspace' under resource group 'clitestzeyavoifb7iy74smt2roepqce7sqojmb2rczyovhs6jjetiupnbujw4jiest7yumuipy' was not found. For more details please go to https://aka.ms/ARMResourceNotFoundFix|Traceback (most recent call last):   File "D:\repos\azure-cli\src\azure-cli-testsdk\azure\cli\testsdk\base.py", line 289, in _in_process_execute     self.exit_code = cli_ctx.invoke(shlex.split(command), out_file=stdout_buf) or 0   File "D:\repos\env3\lib\site-packages\knack\cli.py", line 226, in invoke     exit_code = self.exception_handler(ex)   File "D:\repos\azure-cli\src\azure-cli-core\azure\cli\core\__init__.py", line 119, in exception_handler     return handle_exception(ex)   File "D:\repo||2020-10-23 08:03:48.930277|2020-10-23 08:03:50.734746|
|step__alertrules_get_get_a_fusion_alert_rule_|failed|3|Traceback (most recent call last):   File "D:\repos\azure-cli\src\azure-cli-core\azure\cli\core\commands\arm.py", line 754, in handler     return getter(**args)   File "D:\repos\azure-cli-extensions\src\securityinsight\azext_sentinel\generated\custom.py", line 27, in sentinel_alert_rule_show     return client.get(resource_group_name=resource_group_name,   File "D:\repos\azure-cli-extensions\src\securityinsight\azext_sentinel\vendored_sdks\securityinsight\operations\_alert_rule_operations.py", li||2020-10-23 08:03:50.739812|2020-10-23 08:03:51.468254|
|step__alertrules_get|failed|3|Traceback (most recent call last):   File "D:\repos\azure-cli\src\azure-cli-core\azure\cli\core\commands\arm.py", line 754, in handler     return getter(**args)   File "D:\repos\azure-cli-extensions\src\securityinsight\azext_sentinel\generated\custom.py", line 27, in sentinel_alert_rule_show     return client.get(resource_group_name=resource_group_name,   File "D:\repos\azure-cli-extensions\src\securityinsight\azext_sentinel\vendored_sdks\securityinsight\operations\_alert_rule_operations.py", li||2020-10-23 08:03:51.471256|2020-10-23 08:03:52.098740|
|step__alertrules_get_get_a_scheduled_alert_rule_|failed|3|Traceback (most recent call last):   File "D:\repos\azure-cli\src\azure-cli-core\azure\cli\core\commands\arm.py", line 754, in handler     return getter(**args)   File "D:\repos\azure-cli-extensions\src\securityinsight\azext_sentinel\generated\custom.py", line 27, in sentinel_alert_rule_show     return client.get(resource_group_name=resource_group_name,   File "D:\repos\azure-cli-extensions\src\securityinsight\azext_sentinel\vendored_sdks\securityinsight\operations\_alert_rule_operations.py", li||2020-10-23 08:03:52.104756|2020-10-23 08:03:52.854595|
|step__alertrules_get_get_all_alert_rules_|failed|(ResourceNotFound) The Resource 'Microsoft.OperationalInsights/workspaces/myWorkspace' under resource group 'clitestzeyavoifb7iy74smt2roepqce7sqojmb2rczyovhs6jjetiupnbujw4jiest7yumuipy' was not found. For more details please go to https://aka.ms/ARMResourceNotFoundFix|Traceback (most recent call last):   File "D:\repos\azure-cli\src\azure-cli-testsdk\azure\cli\testsdk\base.py", line 289, in _in_process_execute     self.exit_code = cli_ctx.invoke(shlex.split(command), out_file=stdout_buf) or 0   File "D:\repos\env3\lib\site-packages\knack\cli.py", line 226, in invoke     exit_code = self.exception_handler(ex)   File "D:\repos\azure-cli\src\azure-cli-core\azure\cli\core\__init__.py", line 119, in exception_handler     return handle_exception(ex)   File "D:\repo||2020-10-23 08:03:52.857596|2020-10-23 08:03:53.506282|
|step__alertrules_get_get_an_action_of_alert_rule_|failed|(ResourceNotFound) The Resource 'Microsoft.OperationalInsights/workspaces/myWorkspace' under resource group 'clitestzeyavoifb7iy74smt2roepqce7sqojmb2rczyovhs6jjetiupnbujw4jiest7yumuipy' was not found. For more details please go to https://aka.ms/ARMResourceNotFoundFix|Traceback (most recent call last):   File "D:\repos\azure-cli\src\azure-cli-testsdk\azure\cli\testsdk\base.py", line 289, in _in_process_execute     self.exit_code = cli_ctx.invoke(shlex.split(command), out_file=stdout_buf) or 0   File "D:\repos\env3\lib\site-packages\knack\cli.py", line 226, in invoke     exit_code = self.exception_handler(ex)   File "D:\repos\azure-cli\src\azure-cli-core\azure\cli\core\__init__.py", line 119, in exception_handler     return handle_exception(ex)   File "D:\repo||2020-10-23 08:03:53.513125|2020-10-23 08:03:54.211946|
|step__alertrules_delete|failed|(ResourceNotFound) The Resource 'Microsoft.OperationalInsights/workspaces/myWorkspace' under resource group 'clitestzeyavoifb7iy74smt2roepqce7sqojmb2rczyovhs6jjetiupnbujw4jiest7yumuipy' was not found. For more details please go to https://aka.ms/ARMResourceNotFoundFix|Traceback (most recent call last):   File "D:\repos\azure-cli\src\azure-cli-testsdk\azure\cli\testsdk\base.py", line 289, in _in_process_execute     self.exit_code = cli_ctx.invoke(shlex.split(command), out_file=stdout_buf) or 0   File "D:\repos\env3\lib\site-packages\knack\cli.py", line 226, in invoke     exit_code = self.exception_handler(ex)   File "D:\repos\azure-cli\src\azure-cli-core\azure\cli\core\__init__.py", line 119, in exception_handler     return handle_exception(ex)   File "D:\repo||2020-10-23 08:03:54.219947|2020-10-23 08:03:54.934383|
|step__alertrules_delete_delete_an_alert_rule_|failed|(ResourceNotFound) The Resource 'Microsoft.OperationalInsights/workspaces/myWorkspace' under resource group 'clitestzeyavoifb7iy74smt2roepqce7sqojmb2rczyovhs6jjetiupnbujw4jiest7yumuipy' was not found. For more details please go to https://aka.ms/ARMResourceNotFoundFix|Traceback (most recent call last):   File "D:\repos\azure-cli\src\azure-cli-testsdk\azure\cli\testsdk\base.py", line 289, in _in_process_execute     self.exit_code = cli_ctx.invoke(shlex.split(command), out_file=stdout_buf) or 0   File "D:\repos\env3\lib\site-packages\knack\cli.py", line 226, in invoke     exit_code = self.exception_handler(ex)   File "D:\repos\azure-cli\src\azure-cli-core\azure\cli\core\__init__.py", line 119, in exception_handler     return handle_exception(ex)   File "D:\repo||2020-10-23 08:03:54.940385|2020-10-23 08:03:55.643572|
Coverage: 0/11
